Exception on /pmg/myday [GET]
Traceback (most recent call last):
  File "/home/tylerobri/.virtualenvs/myvirtualenv/lib/python3.10/site-packages/sqlalchemy/engine/base.py", line 1967, in _exec_single_context
    self.dialect.do_execute(
  File "/home/tylerobri/.virtualenvs/myvirtualenv/lib/python3.10/site-packages/sqlalchemy/engine/default.py", line 924, in do_execute
    cursor.execute(statement, parameters)
  File "/home/tylerobri/.virtualenvs/myvirtualenv/lib/python3.10/site-packages/MySQLdb/cursors.py", line 179, in execute
    res = self._query(mogrified_query)
  File "/home/tylerobri/.virtualenvs/myvirtualenv/lib/python3.10/site-packages/MySQLdb/cursors.py", line 330, in _query
    db.query(q)
  File "/home/tylerobri/.virtualenvs/myvirtualenv/lib/python3.10/site-packages/MySQLdb/connections.py", line 261, in query
    _mysql.connection.query(self, query)
MySQLdb.OperationalError: (4031, 'The client was disconnected by the server because of inactivity. See wait_timeout and interactive_timeout for configuring this behavior.')

The above exception was the direct cause of the following exception:

Traceback (most recent call last):
  File "/home/tylerobri/.virtualenvs/myvirtualenv/lib/python3.10/site-packages/flask/app.py", line 1473, in wsgi_app
    response = self.full_dispatch_request()
  File "/home/tylerobri/.virtualenvs/myvirtualenv/lib/python3.10/site-packages/flask/app.py", line 882, in full_dispatch_request
    rv = self.handle_user_exception(e)
  File "/home/tylerobri/.virtualenvs/myvirtualenv/lib/python3.10/site-packages/flask/app.py", line 880, in full_dispatch_request
    rv = self.dispatch_request()
  File "/home/tylerobri/.virtualenvs/myvirtualenv/lib/python3.10/site-packages/flask/app.py", line 865, in dispatch_request
    return self.ensure_sync(self.view_functions[rule.endpoint])(**view_args)  # type: ignore[no-any-return]
  File "/home/tylerobri/.virtualenvs/myvirtualenv/lib/python3.10/site-packages/flask_login/utils.py", line 284, in decorated_view
    elif not current_user.is_authenticated:
  File "/home/tylerobri/.virtualenvs/myvirtualenv/lib/python3.10/site-packages/werkzeug/local.py", line 318, in __get__
    obj = instance._get_current_object()
  File "/home/tylerobri/.virtualenvs/myvirtualenv/lib/python3.10/site-packages/werkzeug/local.py", line 526, in _get_current_object
    return get_name(local())
  File "/home/tylerobri/.virtualenvs/myvirtualenv/lib/python3.10/site-packages/flask_login/utils.py", line 25, in <lambda>
    current_user = LocalProxy(lambda: _get_user())
  File "/home/tylerobri/.virtualenvs/myvirtualenv/lib/python3.10/site-packages/flask_login/utils.py", line 370, in _get_user
    current_app.login_manager._load_user()
  File "/home/tylerobri/.virtualenvs/myvirtualenv/lib/python3.10/site-packages/flask_login/login_manager.py", line 364, in _load_user
    user = self._user_callback(user_id)
  File "/home/tylerobri/tyler_webb/main.py", line 58, in load_user
    return User.query.get(int(user_id))
  File "<string>", line 2, in get
  File "/home/tylerobri/.virtualenvs/myvirtualenv/lib/python3.10/site-packages/sqlalchemy/util/deprecations.py", line 386, in warned
    return fn(*args, **kwargs)  # type: ignore[no-any-return]
  File "/home/tylerobri/.virtualenvs/myvirtualenv/lib/python3.10/site-packages/sqlalchemy/orm/query.py", line 1127, in get
    return self._get_impl(ident, loading.load_on_pk_identity)
  File "/home/tylerobri/.virtualenvs/myvirtualenv/lib/python3.10/site-packages/sqlalchemy/orm/query.py", line 1136, in _get_impl
    return self.session._get_impl(
  File "/home/tylerobri/.virtualenvs/myvirtualenv/lib/python3.10/site-packages/sqlalchemy/orm/session.py", line 3862, in _get_impl
    return db_load_fn(
  File "/home/tylerobri/.virtualenvs/myvirtualenv/lib/python3.10/site-packages/sqlalchemy/orm/loading.py", line 694, in load_on_pk_identity
    session.execute(
  File "/home/tylerobri/.virtualenvs/myvirtualenv/lib/python3.10/site-packages/sqlalchemy/orm/session.py", line 2351, in execute
    return self._execute_internal(
  File "/home/tylerobri/.virtualenvs/myvirtualenv/lib/python3.10/site-packages/sqlalchemy/orm/session.py", line 2236, in _execute_internal
    result: Result[Any] = compile_state_cls.orm_execute_statement(
  File "/home/tylerobri/.virtualenvs/myvirtualenv/lib/python3.10/site-packages/sqlalchemy/orm/context.py", line 293, in orm_execute_statement
    result = conn.execute(
  File "/home/tylerobri/.virtualenvs/myvirtualenv/lib/python3.10/site-packages/sqlalchemy/engine/base.py", line 1418, in execute
    return meth(
  File "/home/tylerobri/.virtualenvs/myvirtualenv/lib/python3.10/site-packages/sqlalchemy/sql/elements.py", line 515, in _execute_on_connection
    return connection._execute_clauseelement(
  File "/home/tylerobri/.virtualenvs/myvirtualenv/lib/python3.10/site-packages/sqlalchemy/engine/base.py", line 1640, in _execute_clauseelement
    ret = self._execute_context(
  File "/home/tylerobri/.virtualenvs/myvirtualenv/lib/python3.10/site-packages/sqlalchemy/engine/base.py", line 1846, in _execute_context
    return self._exec_single_context(
  File "/home/tylerobri/.virtualenvs/myvirtualenv/lib/python3.10/site-packages/sqlalchemy/engine/base.py", line 1986, in _exec_single_context
    self._handle_dbapi_exception(
  File "/home/tylerobri/.virtualenvs/myvirtualenv/lib/python3.10/site-packages/sqlalchemy/engine/base.py", line 2353, in _handle_dbapi_exception
    raise sqlalchemy_exception.with_traceback(exc_info[2]) from e
  File "/home/tylerobri/.virtualenvs/myvirtualenv/lib/python3.10/site-packages/sqlalchemy/engine/base.py", line 1967, in _exec_single_context
    self.dialect.do_execute(
  File "/home/tylerobri/.virtualenvs/myvirtualenv/lib/python3.10/site-packages/sqlalchemy/engine/default.py", line 924, in do_execute
    cursor.execute(statement, parameters)
  File "/home/tylerobri/.virtualenvs/myvirtualenv/lib/python3.10/site-packages/MySQLdb/cursors.py", line 179, in execute
    res = self._query(mogrified_query)
  File "/home/tylerobri/.virtualenvs/myvirtualenv/lib/python3.10/site-packages/MySQLdb/cursors.py", line 330, in _query
    db.query(q)
  File "/home/tylerobri/.virtualenvs/myvirtualenv/lib/python3.10/site-packages/MySQLdb/connections.py", line 261, in query
    _mysql.connection.query(self, query)
sqlalchemy.exc.OperationalError: (MySQLdb.OperationalError) (4031, 'The client was disconnected by the server because of inactivity. See wait_timeout and interactive_timeout for configuring this behavior.')
[SQL: SELECT user.id AS user_id, user.username AS user_username, user.email AS user_email, user.password AS user_password, user.`firstName` AS `user_firstName`, user.`lastName` AS `user_lastName`, user.verified AS user_verified 
FROM user 
WHERE user.id = %s]
[parameters: (1,)]
(Background on this error at: https://sqlalche.me/e/20/e3q8)
Exception on /base/blogg [GET]
Traceback (most recent call last):
  File "/home/tylerobri/.virtualenvs/myvirtualenv/lib/python3.10/site-packages/flask/app.py", line 1473, in wsgi_app
    response = self.full_dispatch_request()
  File "/home/tylerobri/.virtualenvs/myvirtualenv/lib/python3.10/site-packages/flask/app.py", line 882, in full_dispatch_request
    rv = self.handle_user_exception(e)
  File "/home/tylerobri/.virtualenvs/myvirtualenv/lib/python3.10/site-packages/flask/app.py", line 880, in full_dispatch_request
    rv = self.dispatch_request()
  File "/home/tylerobri/.virtualenvs/myvirtualenv/lib/python3.10/site-packages/flask/app.py", line 865, in dispatch_request
    return self.ensure_sync(self.view_functions[rule.endpoint])(**view_args)  # type: ignore[no-any-return]
  File "/home/tylerobri/tyler_webb/blueprints/base.py", line 42, in blogg
    content = get_blog_content_for_section(section_name)
  File "/home/tylerobri/tyler_webb/blueprints/base.py", line 33, in get_blog_content_for_section
    content = BusinessBlogg.query.all()
NameError: name 'BusinessBlogg' is not defined
Server Error: 500 Internal Server Error: The server encountered an internal error and was unable to complete your request. Either the server is overloaded or there is an error in the application., User: None, Route: https://www.tylerobrien.se/base/blogg, Method: GET, Data: b''
Exception on /pmg/streak/14/details [GET]
Traceback (most recent call last):
  File "/home/tylerobri/.virtualenvs/myvirtualenv/lib/python3.10/site-packages/flask/app.py", line 1473, in wsgi_app
    response = self.full_dispatch_request()
  File "/home/tylerobri/.virtualenvs/myvirtualenv/lib/python3.10/site-packages/flask/app.py", line 882, in full_dispatch_request
    rv = self.handle_user_exception(e)
  File "/home/tylerobri/.virtualenvs/myvirtualenv/lib/python3.10/site-packages/flask/app.py", line 880, in full_dispatch_request
    rv = self.dispatch_request()
  File "/home/tylerobri/.virtualenvs/myvirtualenv/lib/python3.10/site-packages/flask/app.py", line 865, in dispatch_request
    return self.ensure_sync(self.view_functions[rule.endpoint])(**view_args)  # type: ignore[no-any-return]
  File "/home/tylerobri/tyler_webb/blueprints/pmg.py", line 317, in streak_details
    streakdetail = Streak.query.filter_by(user_id=current_user.id, id = streak_id).first()
AttributeError: 'AnonymousUserMixin' object has no attribute 'id'
Server Error: 500 Internal Server Error: The server encountered an internal error and was unable to complete your request. Either the server is overloaded or there is an error in the application., User: None, Route: https://www.tylerobrien.se/pmg/streak/14/details, Method: GET, Data: b''
