Exception on /pmg/month [GET]
Traceback (most recent call last):
  File "C:\Users\Admin\PycharmProjects\tyler_webb\.venv\Lib\site-packages\sqlalchemy\engine\base.py", line 145, in __init__
    self._dbapi_connection = engine.raw_connection()
                             ^^^^^^^^^^^^^^^^^^^^^^^
  File "C:\Users\Admin\PycharmProjects\tyler_webb\.venv\Lib\site-packages\sqlalchemy\engine\base.py", line 3303, in raw_connection
    return self.pool.connect()
           ^^^^^^^^^^^^^^^^^^^
  File "C:\Users\Admin\PycharmProjects\tyler_webb\.venv\Lib\site-packages\sqlalchemy\pool\base.py", line 449, in connect
    return _ConnectionFairy._checkout(self)
           ^^^^^^^^^^^^^^^^^^^^^^^^^^^^^^^^
  File "C:\Users\Admin\PycharmProjects\tyler_webb\.venv\Lib\site-packages\sqlalchemy\pool\base.py", line 1263, in _checkout
    fairy = _ConnectionRecord.checkout(pool)
            ^^^^^^^^^^^^^^^^^^^^^^^^^^^^^^^^
  File "C:\Users\Admin\PycharmProjects\tyler_webb\.venv\Lib\site-packages\sqlalchemy\pool\base.py", line 717, in checkout
    with util.safe_reraise():
  File "C:\Users\Admin\PycharmProjects\tyler_webb\.venv\Lib\site-packages\sqlalchemy\util\langhelpers.py", line 146, in __exit__
    raise exc_value.with_traceback(exc_tb)
  File "C:\Users\Admin\PycharmProjects\tyler_webb\.venv\Lib\site-packages\sqlalchemy\pool\base.py", line 715, in checkout
    dbapi_connection = rec.get_connection()
                       ^^^^^^^^^^^^^^^^^^^^
  File "C:\Users\Admin\PycharmProjects\tyler_webb\.venv\Lib\site-packages\sqlalchemy\pool\base.py", line 837, in get_connection
    self.__connect()
  File "C:\Users\Admin\PycharmProjects\tyler_webb\.venv\Lib\site-packages\sqlalchemy\pool\base.py", line 900, in __connect
    with util.safe_reraise():
  File "C:\Users\Admin\PycharmProjects\tyler_webb\.venv\Lib\site-packages\sqlalchemy\util\langhelpers.py", line 146, in __exit__
    raise exc_value.with_traceback(exc_tb)
  File "C:\Users\Admin\PycharmProjects\tyler_webb\.venv\Lib\site-packages\sqlalchemy\pool\base.py", line 896, in __connect
    self.dbapi_connection = connection = pool._invoke_creator(self)
                                         ^^^^^^^^^^^^^^^^^^^^^^^^^^
  File "C:\Users\Admin\PycharmProjects\tyler_webb\.venv\Lib\site-packages\sqlalchemy\engine\create.py", line 643, in connect
    return dialect.connect(*cargs, **cparams)
           ^^^^^^^^^^^^^^^^^^^^^^^^^^^^^^^^^^
  File "C:\Users\Admin\PycharmProjects\tyler_webb\.venv\Lib\site-packages\sqlalchemy\engine\default.py", line 616, in connect
    return self.loaded_dbapi.connect(*cargs, **cparams)
           ^^^^^^^^^^^^^^^^^^^^^^^^^^^^^^^^^^^^^^^^^^^^
  File "C:\Users\Admin\PycharmProjects\tyler_webb\.venv\Lib\site-packages\MySQLdb\__init__.py", line 121, in Connect
    return Connection(*args, **kwargs)
           ^^^^^^^^^^^^^^^^^^^^^^^^^^^
  File "C:\Users\Admin\PycharmProjects\tyler_webb\.venv\Lib\site-packages\MySQLdb\connections.py", line 195, in __init__
    super().__init__(*args, **kwargs2)
MySQLdb.OperationalError: (2013, "Lost connection to server at 'handshake: reading initial communication packet', system error: 0")

The above exception was the direct cause of the following exception:

Traceback (most recent call last):
  File "C:\Users\Admin\PycharmProjects\tyler_webb\.venv\Lib\site-packages\flask\app.py", line 1463, in wsgi_app
    response = self.full_dispatch_request()
               ^^^^^^^^^^^^^^^^^^^^^^^^^^^^
  File "C:\Users\Admin\PycharmProjects\tyler_webb\.venv\Lib\site-packages\flask\app.py", line 872, in full_dispatch_request
    rv = self.handle_user_exception(e)
         ^^^^^^^^^^^^^^^^^^^^^^^^^^^^^
  File "C:\Users\Admin\PycharmProjects\tyler_webb\.venv\Lib\site-packages\flask\app.py", line 870, in full_dispatch_request
    rv = self.dispatch_request()
         ^^^^^^^^^^^^^^^^^^^^^^^
  File "C:\Users\Admin\PycharmProjects\tyler_webb\.venv\Lib\site-packages\flask\app.py", line 855, in dispatch_request
    return self.ensure_sync(self.view_functions[rule.endpoint])(**view_args)  # type: ignore[no-any-return]
           ^^^^^^^^^^^^^^^^^^^^^^^^^^^^^^^^^^^^^^^^^^^^^^^^^^^^^^^^^^^^^^^^^
  File "C:\Users\Admin\PycharmProjects\tyler_webb\blueprints\pmg.py", line 547, in month
    update_dagar(current_user.id, Dagar)  # Uppdatera Dagar-modellen
                 ^^^^^^^^^^^^^^^
  File "C:\Users\Admin\PycharmProjects\tyler_webb\.venv\Lib\site-packages\werkzeug\local.py", line 311, in __get__
    obj = instance._get_current_object()
          ^^^^^^^^^^^^^^^^^^^^^^^^^^^^^^
  File "C:\Users\Admin\PycharmProjects\tyler_webb\.venv\Lib\site-packages\werkzeug\local.py", line 515, in _get_current_object
    return get_name(local())
                    ^^^^^^^
  File "C:\Users\Admin\PycharmProjects\tyler_webb\.venv\Lib\site-packages\flask_login\utils.py", line 25, in <lambda>
    current_user = LocalProxy(lambda: _get_user())
                                      ^^^^^^^^^^^
  File "C:\Users\Admin\PycharmProjects\tyler_webb\.venv\Lib\site-packages\flask_login\utils.py", line 370, in _get_user
    current_app.login_manager._load_user()
  File "C:\Users\Admin\PycharmProjects\tyler_webb\.venv\Lib\site-packages\flask_login\login_manager.py", line 364, in _load_user
    user = self._user_callback(user_id)
           ^^^^^^^^^^^^^^^^^^^^^^^^^^^^
  File "C:\Users\Admin\PycharmProjects\tyler_webb\main.py", line 61, in load_user
    return User.query.get(int(user_id))
           ^^^^^^^^^^^^^^^^^^^^^^^^^^^^
  File "<string>", line 2, in get
  File "C:\Users\Admin\PycharmProjects\tyler_webb\.venv\Lib\site-packages\sqlalchemy\util\deprecations.py", line 386, in warned
    return fn(*args, **kwargs)  # type: ignore[no-any-return]
           ^^^^^^^^^^^^^^^^^^^
  File "C:\Users\Admin\PycharmProjects\tyler_webb\.venv\Lib\site-packages\sqlalchemy\orm\query.py", line 1127, in get
    return self._get_impl(ident, loading.load_on_pk_identity)
           ^^^^^^^^^^^^^^^^^^^^^^^^^^^^^^^^^^^^^^^^^^^^^^^^^^
  File "C:\Users\Admin\PycharmProjects\tyler_webb\.venv\Lib\site-packages\sqlalchemy\orm\query.py", line 1136, in _get_impl
    return self.session._get_impl(
           ^^^^^^^^^^^^^^^^^^^^^^^
  File "C:\Users\Admin\PycharmProjects\tyler_webb\.venv\Lib\site-packages\sqlalchemy\orm\session.py", line 3817, in _get_impl
    return db_load_fn(
           ^^^^^^^^^^^
  File "C:\Users\Admin\PycharmProjects\tyler_webb\.venv\Lib\site-packages\sqlalchemy\orm\loading.py", line 694, in load_on_pk_identity
    session.execute(
  File "C:\Users\Admin\PycharmProjects\tyler_webb\.venv\Lib\site-packages\sqlalchemy\orm\session.py", line 2306, in execute
    return self._execute_internal(
           ^^^^^^^^^^^^^^^^^^^^^^^
  File "C:\Users\Admin\PycharmProjects\tyler_webb\.venv\Lib\site-packages\sqlalchemy\orm\session.py", line 2181, in _execute_internal
    conn = self._connection_for_bind(bind)
           ^^^^^^^^^^^^^^^^^^^^^^^^^^^^^^^
  File "C:\Users\Admin\PycharmProjects\tyler_webb\.venv\Lib\site-packages\sqlalchemy\orm\session.py", line 2050, in _connection_for_bind
    return trans._connection_for_bind(engine, execution_options)
           ^^^^^^^^^^^^^^^^^^^^^^^^^^^^^^^^^^^^^^^^^^^^^^^^^^^^^
  File "<string>", line 2, in _connection_for_bind
  File "C:\Users\Admin\PycharmProjects\tyler_webb\.venv\Lib\site-packages\sqlalchemy\orm\state_changes.py", line 139, in _go
    ret_value = fn(self, *arg, **kw)
                ^^^^^^^^^^^^^^^^^^^^
  File "C:\Users\Admin\PycharmProjects\tyler_webb\.venv\Lib\site-packages\sqlalchemy\orm\session.py", line 1144, in _connection_for_bind
    conn = bind.connect()
           ^^^^^^^^^^^^^^
  File "C:\Users\Admin\PycharmProjects\tyler_webb\.venv\Lib\site-packages\sqlalchemy\engine\base.py", line 3279, in connect
    return self._connection_cls(self)
           ^^^^^^^^^^^^^^^^^^^^^^^^^^
  File "C:\Users\Admin\PycharmProjects\tyler_webb\.venv\Lib\site-packages\sqlalchemy\engine\base.py", line 147, in __init__
    Connection._handle_dbapi_exception_noconnection(
  File "C:\Users\Admin\PycharmProjects\tyler_webb\.venv\Lib\site-packages\sqlalchemy\engine\base.py", line 2443, in _handle_dbapi_exception_noconnection
    raise sqlalchemy_exception.with_traceback(exc_info[2]) from e
  File "C:\Users\Admin\PycharmProjects\tyler_webb\.venv\Lib\site-packages\sqlalchemy\engine\base.py", line 145, in __init__
    self._dbapi_connection = engine.raw_connection()
                             ^^^^^^^^^^^^^^^^^^^^^^^
  File "C:\Users\Admin\PycharmProjects\tyler_webb\.venv\Lib\site-packages\sqlalchemy\engine\base.py", line 3303, in raw_connection
    return self.pool.connect()
           ^^^^^^^^^^^^^^^^^^^
  File "C:\Users\Admin\PycharmProjects\tyler_webb\.venv\Lib\site-packages\sqlalchemy\pool\base.py", line 449, in connect
    return _ConnectionFairy._checkout(self)
           ^^^^^^^^^^^^^^^^^^^^^^^^^^^^^^^^
  File "C:\Users\Admin\PycharmProjects\tyler_webb\.venv\Lib\site-packages\sqlalchemy\pool\base.py", line 1263, in _checkout
    fairy = _ConnectionRecord.checkout(pool)
            ^^^^^^^^^^^^^^^^^^^^^^^^^^^^^^^^
  File "C:\Users\Admin\PycharmProjects\tyler_webb\.venv\Lib\site-packages\sqlalchemy\pool\base.py", line 717, in checkout
    with util.safe_reraise():
  File "C:\Users\Admin\PycharmProjects\tyler_webb\.venv\Lib\site-packages\sqlalchemy\util\langhelpers.py", line 146, in __exit__
    raise exc_value.with_traceback(exc_tb)
  File "C:\Users\Admin\PycharmProjects\tyler_webb\.venv\Lib\site-packages\sqlalchemy\pool\base.py", line 715, in checkout
    dbapi_connection = rec.get_connection()
                       ^^^^^^^^^^^^^^^^^^^^
  File "C:\Users\Admin\PycharmProjects\tyler_webb\.venv\Lib\site-packages\sqlalchemy\pool\base.py", line 837, in get_connection
    self.__connect()
  File "C:\Users\Admin\PycharmProjects\tyler_webb\.venv\Lib\site-packages\sqlalchemy\pool\base.py", line 900, in __connect
    with util.safe_reraise():
  File "C:\Users\Admin\PycharmProjects\tyler_webb\.venv\Lib\site-packages\sqlalchemy\util\langhelpers.py", line 146, in __exit__
    raise exc_value.with_traceback(exc_tb)
  File "C:\Users\Admin\PycharmProjects\tyler_webb\.venv\Lib\site-packages\sqlalchemy\pool\base.py", line 896, in __connect
    self.dbapi_connection = connection = pool._invoke_creator(self)
                                         ^^^^^^^^^^^^^^^^^^^^^^^^^^
  File "C:\Users\Admin\PycharmProjects\tyler_webb\.venv\Lib\site-packages\sqlalchemy\engine\create.py", line 643, in connect
    return dialect.connect(*cargs, **cparams)
           ^^^^^^^^^^^^^^^^^^^^^^^^^^^^^^^^^^
  File "C:\Users\Admin\PycharmProjects\tyler_webb\.venv\Lib\site-packages\sqlalchemy\engine\default.py", line 616, in connect
    return self.loaded_dbapi.connect(*cargs, **cparams)
           ^^^^^^^^^^^^^^^^^^^^^^^^^^^^^^^^^^^^^^^^^^^^
  File "C:\Users\Admin\PycharmProjects\tyler_webb\.venv\Lib\site-packages\MySQLdb\__init__.py", line 121, in Connect
    return Connection(*args, **kwargs)
           ^^^^^^^^^^^^^^^^^^^^^^^^^^^
  File "C:\Users\Admin\PycharmProjects\tyler_webb\.venv\Lib\site-packages\MySQLdb\connections.py", line 195, in __init__
    super().__init__(*args, **kwargs2)
sqlalchemy.exc.OperationalError: (MySQLdb.OperationalError) (2013, "Lost connection to server at 'handshake: reading initial communication packet', system error: 0")
(Background on this error at: https://sqlalche.me/e/20/e3q8)
